 2023-03-02 22:33:08,428 - telegram.ext.dispatcher - ERROR - No error handlers are registered, logging exception.
2023-03-02T22:33:08.431816+00:00 app[worker.1]: Traceback (most recent call last):
2023-03-02T22:33:08.431818+00:00 app[worker.1]:   File "/usr/local/lib/python3.7/site-packages/telegram/ext/dispatcher.py", line 447, in process_update
2023-03-02T22:33:08.431819+00:00 app[worker.1]:     handler.handle_update(update, self, check, context)
2023-03-02T22:33:08.431819+00:00 app[worker.1]:   File "/usr/local/lib/python3.7/site-packages/telegram/ext/conversationhandler.py", line 602, in handle_update
2023-03-02T22:33:08.431820+00:00 app[worker.1]:     new_state = handler.handle_update(update, dispatcher, check_result, context)
2023-03-02T22:33:08.431820+00:00 app[worker.1]:   File "/usr/local/lib/python3.7/site-packages/telegram/ext/handler.py", line 160, in handle_update
2023-03-02T22:33:08.431821+00:00 app[worker.1]:     return self.callback(update, context)
2023-03-02T22:33:08.431821+00:00 app[worker.1]:   File "/app/bot.py", line 288, in follow_twitter
2023-03-02T22:33:08.431821+00:00 app[worker.1]:     update.message.reply_text(text=FOLLOW_TWITTER_TEXT, parse_mode=telegram.ParseMode.MARKDOWN)
2023-03-02T22:33:08.431821+00:00 app[worker.1]:   File "/usr/local/lib/python3.7/site-packages/telegram/message.py", line 715, in reply_text
2023-03-02T22:33:08.431822+00:00 app[worker.1]:     entities=entities,
2023-03-02T22:33:08.431822+00:00 app[worker.1]:   File "/usr/local/lib/python3.7/site-packages/telegram/bot.py", line 127, in decorator
2023-03-02T22:33:08.431823+00:00 app[worker.1]:     result = func(*args, **kwargs)
2023-03-02T22:33:08.431823+00:00 app[worker.1]:   File "/usr/local/lib/python3.7/site-packages/telegram/bot.py", line 483, in send_message
2023-03-02T22:33:08.431824+00:00 app[worker.1]:     api_kwargs=api_kwargs,
2023-03-02T22:33:08.431824+00:00 app[worker.1]:   File "/usr/local/lib/python3.7/site-packages/telegram/bot.py", line 296, in _message
2023-03-02T22:33:08.431825+00:00 app[worker.1]:     result = self._post(endpoint, data, timeout=timeout, api_kwargs=api_kwargs)
2023-03-02T22:33:08.431825+00:00 app[worker.1]:   File "/usr/local/lib/python3.7/site-packages/telegram/bot.py", line 260, in _post
2023-03-02T22:33:08.431825+00:00 app[worker.1]:     f'{self.base_url}/{endpoint}', data=data, timeout=effective_timeout
2023-03-02T22:33:08.431826+00:00 app[worker.1]:   File "/usr/local/lib/python3.7/site-packages/telegram/utils/request.py", line 355, in post
2023-03-02T22:33:08.431826+00:00 app[worker.1]:     **urlopen_kwargs,
2023-03-02T22:33:08.431826+00:00 app[worker.1]:   File "/usr/local/lib/python3.7/site-packages/telegram/utils/request.py", line 273, in _request_wrapper
2023-03-02T22:33:08.431826+00:00 app[worker.1]:     raise BadRequest(message)
2023-03-02T22:33:08.431826+00:00 app[worker.1]: telegram.error.BadRequest: Can't parse entities: can't find end of the entity starting at byte offset 62


Traceback (most recent call last):
2023-03-02T23:14:59.941779+00:00 app[worker.1]:   File "/usr/local/lib/python3.7/site-packages/telegram/ext/dispatcher.py", line 447, in process_update
2023-03-02T23:14:59.941786+00:00 app[worker.1]:     handler.handle_update(update, self, check, context)
2023-03-02T23:14:59.941786+00:00 app[worker.1]:   File "/usr/local/lib/python3.7/site-packages/telegram/ext/conversationhandler.py", line 602, in handle_update
2023-03-02T23:14:59.941787+00:00 app[worker.1]:     new_state = handler.handle_update(update, dispatcher, check_result, context)
2023-03-02T23:14:59.941788+00:00 app[worker.1]:   File "/usr/local/lib/python3.7/site-packages/telegram/ext/handler.py", line 160, in handle_update
2023-03-02T23:14:59.941788+00:00 app[worker.1]:     return self.callback(update, context)
2023-03-02T23:14:59.941788+00:00 app[worker.1]:   File "/app/bot.py", line 280, in follow_telegram
2023-03-02T23:14:59.941789+00:00 app[worker.1]:     update.message.reply_text(text=escape_markdown(MAKE_SURE_TELEGRAM, 2))
2023-03-02T23:14:59.941790+00:00 app[worker.1]: TypeError: escape_markdown() takes 1 positional argument but 2 were given
2023-03-02T23:15:14.015646+00:00 app[worker.1]: 2023-03-02 23:15:14,015 - telegram.ext.dispatcher - ERROR - No error handlers are registered, logging exception.
2023-03-02T23:15:14.015661+00:00 app[worker.1]: Traceback (most recent call last):
2023-03-02T23:15:14.015661+00:00 app[worker.1]:   File "/usr/local/lib/python3.7/site-packages/telegram/ext/dispatcher.py", line 447, in process_update
2023-03-02T23:15:14.015662+00:00 app[worker.1]:     handler.handle_update(update, self, check, context)
2023-03-02T23:15:14.015662+00:00 app[worker.1]:   File "/usr/local/lib/python3.7/site-packages/telegram/ext/conversationhandler.py", line 602, in handle_update
2023-03-02T23:15:14.015663+00:00 app[worker.1]:     new_state = handler.handle_update(update, dispatcher, check_result, context)
2023-03-02T23:15:14.015663+00:00 app[worker.1]:   File "/usr/local/lib/python3.7/site-packages/telegram/ext/handler.py", line 160, in handle_update
2023-03-02T23:15:14.015663+00:00 app[worker.1]:     return self.callback(update, context)
2023-03-02T23:15:14.015663+00:00 app[worker.1]:   File "/app/bot.py", line 280, in follow_telegram
2023-03-02T23:15:14.015664+00:00 app[worker.1]:     update.message.reply_text(text=escape_markdown(MAKE_SURE_TELEGRAM, 2))
2023-03-02T23:15:14.015664+00:00 app[worker.1]: TypeError: escape_markdown() takes 1 positional argument but 2 were given
