 2023-03-02 23:58:25,146 - apscheduler.scheduler - INFO - Scheduler started
2023-03-02T23:58:55.707608+00:00 app[worker.1]: 2023-03-02 23:58:55,704 - telegram.ext.dispatcher - ERROR - No error handlers are registered, logging exception.
2023-03-02T23:58:55.707626+00:00 app[worker.1]: Traceback (most recent call last):
2023-03-02T23:58:55.707627+00:00 app[worker.1]:   File "/usr/local/lib/python3.7/site-packages/telegram/ext/dispatcher.py", line 447, in process_update
2023-03-02T23:58:55.707628+00:00 app[worker.1]:     handler.handle_update(update, self, check, context)
2023-03-02T23:58:55.707629+00:00 app[worker.1]:   File "/usr/local/lib/python3.7/site-packages/telegram/ext/conversationhandler.py", line 602, in handle_update
2023-03-02T23:58:55.707630+00:00 app[worker.1]:     new_state = handler.handle_update(update, dispatcher, check_result, context)
2023-03-02T23:58:55.707631+00:00 app[worker.1]:   File "/usr/local/lib/python3.7/site-packages/telegram/ext/handler.py", line 160, in handle_update
2023-03-02T23:58:55.707631+00:00 app[worker.1]:     return self.callback(update, context)
2023-03-02T23:58:55.707631+00:00 app[worker.1]:   File "/app/bot.py", line 303, in follow_twitter
2023-03-02T23:58:55.707632+00:00 app[worker.1]:     update.message.reply_text(text=FOLLOW_TWITTER_TEXT, parse_mode=telegram.ParseMode.MARKDOWN)
2023-03-02T23:58:55.707632+00:00 app[worker.1]:   File "/usr/local/lib/python3.7/site-packages/telegram/message.py", line 715, in reply_text
2023-03-02T23:58:55.707637+00:00 app[worker.1]:     entities=entities,
2023-03-02T23:58:55.707637+00:00 app[worker.1]:   File "/usr/local/lib/python3.7/site-packages/telegram/bot.py", line 127, in decorator
2023-03-02T23:58:55.707638+00:00 app[worker.1]:     result = func(*args, **kwargs)
2023-03-02T23:58:55.707638+00:00 app[worker.1]:   File "/usr/local/lib/python3.7/site-packages/telegram/bot.py", line 483, in send_message
2023-03-02T23:58:55.707641+00:00 app[worker.1]:     api_kwargs=api_kwargs,
2023-03-02T23:58:55.707641+00:00 app[worker.1]:   File "/usr/local/lib/python3.7/site-packages/telegram/bot.py", line 296, in _message
2023-03-02T23:58:55.707643+00:00 app[worker.1]:     result = self._post(endpoint, data, timeout=timeout, api_kwargs=api_kwargs)
2023-03-02T23:58:55.707643+00:00 app[worker.1]:   File "/usr/local/lib/python3.7/site-packages/telegram/bot.py", line 260, in _post
2023-03-02T23:58:55.707644+00:00 app[worker.1]:     f'{self.base_url}/{endpoint}', data=data, timeout=effective_timeout
2023-03-02T23:58:55.707644+00:00 app[worker.1]:   File "/usr/local/lib/python3.7/site-packages/telegram/utils/request.py", line 355, in post
2023-03-02T23:58:55.707644+00:00 app[worker.1]:     **urlopen_kwargs,
2023-03-02T23:58:55.707645+00:00 app[worker.1]:   File "/usr/local/lib/python3.7/site-packages/telegram/utils/request.py", line 273, in _request_wrapper
2023-03-02T23:58:55.707645+00:00 app[worker.1]:     raise BadRequest(message)
2023-03-02T23:58:55.707645+00:00 app[worker.1]: telegram.error.BadRequest: Can't parse entities: can't find end of the entity starting at byte offset 62
2023-03-02T23:58:56.961888+00:00 app[worker.1]: 